Workbook
Name Slicer_PaymentMethod: #N/A

Sheet Instructions
A1: {=A1:B72} -> 0 | B1: KhanaChahiyo Data Analyst Project
B2: Food delivery order data | 6 months | 8 cities across Nepal
B4: You've just joined KhanaChahiyo, a Nepali food delivery startup, as their first Data Analyst.
B5: The Operations Head has handed you 6 months of raw order data and one instruction: "Tell me what's going on, why, what's coming, and what we should do about it."
B6: Assume today's date is 1 February 2026.
B7: Expect this to take a few hours, not minutes. Google things. Get stuck. That's normal, that's the job.
B9: How this maps to Module 1:
B10: 5 Stages: Collection (already done) -> Cleanup (Part A) -> Exploration (Part B) -> Visualization (Part C, D) -> Statistics (Part E, F)
B11: 4 Types of Analytics: Descriptive - what happened (Part C) -> Diagnostic - why (Part D) -> Predictive - what's next (Part E) -> Prescriptive - what to do (Part F)
B13: Sheets already in this file (don't edit these 5): Orders_Raw, Menu_Price_List, Rider_Directory, Promo_Codes, City_Delivery_Fee.
B14: Sheets YOU will create as you go: Orders_Working, Dashboard, Forecast, WhatIf. The instructions tell you when.
B15: When you're done, save this file as YourName_KhanaChahiyo_Project.xlsx and send it back.
B17: WARM-UP THOUGHT (Collection stage)
A18: W1 | B18: This data was already collected for you by the time you got it. If you were designing KhanaChahiyo's checkout screen from scratch, name ONE more piece of data you'd capture that isn't in this sheet, and why it would help you later. 1-2 lines.
B20: PART 0: QUICK LOOK (before you touch anything)
A21: P0.1 | B21: What's the earliest and the latest Order Date in Orders_Raw?
A22: P0.2 | B22: What's the highest and the lowest Delivery Time Taken recorded?
A23: P0.3 | B23: How many rows have a Customer Rating filled in? How many rows are there in total? What does the gap between those two numbers tell you?
A24: P0.4 | B24: What's the average Customer Rating, ignoring the blanks?
B25: Keep these four answers somewhere safe on this sheet — you'll revisit them at the end of Part A.
B27: PART A: CLEAN-UP
A28: A0 | B28: Right-click the Orders_Raw tab -> Move or Copy -> tick 'Create a copy' -> rename the copy Orders_Working. Do every task below inside Orders_Working. Never touch Orders_Raw again, it's your backup.
A29: A1 | B29: Customer Name has random capitals and extra spacing. Fix it so every name looks like a proper name, e.g. 'Suresh Thapa'.
A30: A2 | B30: Customer Phone is inconsistent, some numbers have '+977-' in front, some don't. Remove the country code from all of them, then insert a dash after the first 4 digits, e.g. 9841-234567.
A31: A3 | B31: Look closely at City. Kathmandu is not always spelled the same way. Find out how many different versions exist in this column — one function you learned lists every distinct value in a range. Then make every city spelled one consistent way, not just Kathmandu.
A32: A4 | B32: Two Order IDs each appear twice in the sheet. Find both pairs and highlight all four rows. Don't delete anything, in a nearby cell or comment, note which row in each pair looks like the more complete / correct entry, and why you think so.
A33: A5 | B33: A few rows have no Order Status at all. Add a new column and mark just these rows 'Needs Review'. Leave every other row's status exactly as it is.
A34: A6 | B34: A few Delivery Time Taken values look impossible for a scooter delivery. Use conditional formatting to highlight anything unrealistic. You decide the cutoff, write it in a cell along with one line on your reasoning.
A35: A7 | B35: Add a column called Customer Type. Work out the number of days between Customer Signup Date and this Order Date. If that gap is 2 days or less, label the row 'New'. Otherwise, 'Returning'.
A36: A8 | B36: Convert your cleaned range into a proper Excel Table. Add a dropdown (Data Validation) on Order Status, limited to Delivered, Cancelled, Returned, nothing else should be typeable there anymore.
A37: A9 | B37: Marketing wants one column that reads like 'ORD-1123 | Kathmandu | Chicken Momo' — Order ID, City and Item Name joined into a single line. Build it.
A38: A10 | B38: Marketing also asked (don't ask why) for City in ALL CAPS in one column, and Payment Method in lowercase in another.
A39: A11 | B39: Go back to your four Part 0 answers. Recalculate all four, now on your cleaned Orders_Working data. Did any of them change? Should the average rating have changed? 1-2 lines.
B41: PART B: EXPLORATION (lookups & formulas)
A42: B1 | B42: Bring in the correct Unit Price for every order from Menu_Price_List, matched on Item Name. A plain lookup will fail on a handful of rows, find out why before you fix it.
A43: B2 | B43: Using Unit Price x Quantity, calculate an Order Amount column.
A44: B3 | B44: Bring in the correct Delivery Fee for every order from City_Delivery_Fee, matched on City.
A45: B4 | B45: Some orders used a Promo Code, some didn't (blank). For the ones that did, calculate a Discount Amount, but check Promo_Codes first, because some codes are a percentage off and others are a flat Rupee amount off. A blank code means 0 discount.
A46: B5 | B46: Calculate Final Amount = Order Amount + Delivery Fee - Discount Amount.
A47: B6 | B47: In Rider_Directory, Rider ID is the LAST column, not the first. Still bring each order's Rider City/Zone and Vehicle Type into Orders_Working, matched on Rider ID. (One lookup function you learned doesn't care which side of the table the match column sits on, that's the one you want here.)
...

Sheet Orders_Work
A1: OrderID | B1: OrderDate | C1: Customer Name | D1: Customer Phone | E1: CustomerSignupDate | F1: Customer Type | G1: City | H1: Restaurant Partner | I1: ItemCategory | J1: ItemName | K1: Quantity | L1: RiderID | M1: PaymentMethod | N1: PromoCode | O1: OrderStatus | P1: Status Review | Q1: CustomerRating | R1: DeliveryTimeTaken_Min | S1: FeedbackText | T1: Order Summary | U1: City Upper | V1: Payment Lower | W1: Unit Price | X1: Order Amount | Y1: Delivery Fee | Z1: Discount Amount | AA1: Final Amount | AB1: Rider City | AC1: Value Tier | AD1: Promo Check
A2: ORD-1001 | B2: 45871 | C2: Bikash Rai | D2: 9887-801759 | E2: 45827 | F2: =IF(B2-E2<=2,"New","Returning") -> Returning | G2: Lalitpur | H2: Yeti Newari Bhoj | I2: Newari Khana | J2: Chatamari | K2: 1 | L2: R-108 | M2: Khalti | O2: Delivered | P2: =IF(O2=""," NEED REVIEW","") | Q2: 4 | R2: 36 | T2: =_xlfn.CONCAT(Table5[[#This Row],[OrderID]]," | ",Table5[[#This Row],[City]]," | ",Table5[[#This Row],[ItemName]]) -> ORD-1001 | Lalitpur | Chatamari | U2: =UPPER(Table5[[#This Row],[City]]) -> LALITPUR | V2: =LOWER(Table5[[#This Row],[PaymentMethod]]) -> khalti | W2: {=_xlfn.XLOOKUP(TRIM(Table5[[#This Row],[ItemName]]), TRIM(Menu_Price_List_tbl[ItemName]),Menu_Price_List_tbl[UnitPrice_NPR])} -> 210 | X2: =W2*K2 -> 210 | Y2: =_xlfn.XLOOKUP(Table5[[#This Row],[City]],City_Delivery_Fee_tbl[City],City_Delivery_Fee_tbl[BaseDeliveryFee_NPR]) -> 50 | Z2: =IF(ISBLANK(Table5[[#This Row],[PromoCode]]), 0, _xlfn.LET( _xlpm.type, _xlfn.XLOOKUP(Table5[[#This Row],[PromoCode]], Promo_Codes!$A$2:$A$9, Promo_Codes!$C$2:$C$9, "Flat"), _xlpm.val, _xlfn.XLOOKUP(Table5[[#This Row],[PromoCode]], Promo_Codes!$A$2:$A$9, Promo_Codes!$D$2:$D$9, 0), IF(_xlpm.type="Percentage", Table5[[#This Row],[Order Amount]]*(_xlpm.val/100), _xlpm.val) ) ) -> 0 | AA2: =Table5[[#This Row],[Order Amount]]+Table5[[#This Row],[Delivery Fee]]-Table5[[#This Row],[Discount Amount]] -> 260 | AB2: =_xlfn.XLOOKUP(Table5[[#This Row],[RiderID]], Rider_Directory!$F$2:$F$26, Rider_Directory!$B$2:$B$26) -> Lalitpur | AC2: {=_xlfn.IFS(Table5[[#This Row],[Final Amount]]<500, "Small", Table5[[#This Row],[Final Amount]]<=1000, "Medium", Table5[[#This Row],[Final Amount]]>1000, "Large")} -> Small | AD2: =_xlfn.LET(_xlpm.expiry,_xlfn.XLOOKUP(Table5[[#This Row],[PromoCode]],Promo_Codes!$A$2:$A$9,Promo_Codes!$F$2:$F$9,DATE(2099,1,1)),IF(Table5[[#This Row],[OrderDate]]>_xlpm.expiry,"Expired Code Used","Valid")) -> Valid
A3: ORD-1002 | B3: 45871 | C3: Prakash Gurung | D3: 9809-541858 | E3: 45871 | F3: =IF(B3-E3<=2,"New","Returning") -> New | G3: Chitwan | H3: Fast Bites | I3: Fast Food | J3: French Fries | K3: 1 | L3: R-123 | M3: eSewa | O3: Cancelled | P3: =IF(O3=""," NEED REVIEW","") | R3: 41 | T3: =_xlfn.CONCAT(Table5[[#This Row],[OrderID]]," | ",Table5[[#This Row],[City]]," | ",Table5[[#This Row],[ItemName]]) -> ORD-1002 | Chitwan | French Fries | U3: =UPPER(Table5[[#This Row],[City]]) -> CHITWAN | V3: =LOWER(Table5[[#This Row],[PaymentMethod]]) -> esewa | W3: {=_xlfn.XLOOKUP(TRIM(Table5[[#This Row],[ItemName]]), TRIM(Menu_Price_List_tbl[ItemName]),Menu_Price_List_tbl[UnitPrice_NPR])} -> 160 | X3: =W3*K3 -> 160 | Y3: =_xlfn.XLOOKUP(Table5[[#This Row],[City]],City_Delivery_Fee_tbl[City],City_Delivery_Fee_tbl[BaseDeliveryFee_NPR]) -> 80 | Z3: =IF(ISBLANK(Table5[[#This Row],[PromoCode]]), 0, _xlfn.LET( _xlpm.type, _xlfn.XLOOKUP(Table5[[#This Row],[PromoCode]], Promo_Codes!$A$2:$A$9, Promo_Codes!$C$2:$C$9, "Flat"), _xlpm.val, _xlfn.XLOOKUP(Table5[[#This Row],[PromoCode]], Promo_Codes!$A$2:$A$9, Promo_Codes!$D$2:$D$9, 0), IF(_xlpm.type="Percentage", Table5[[#This Row],[Order Amount]]*(_xlpm.val/100), _xlpm.val) ) ) -> 0 | AA3: =Table5[[#This Row],[Order Amount]]+Table5[[#This Row],[Delivery Fee]]-Table5[[#This Row],[Discount Amount]] -> 240 | AB3: =_xlfn.XLOOKUP(Table5[[#This Row],[RiderID]], Rider_Directory!$F$2:$F$26, Rider_Directory!$B$2:$B$26) -> Chitwan | AC3: {=_xlfn.IFS(Table5[[#This Row],[Final Amount]]<500, "Small", Table5[[#This Row],[Final Amount]]<=1000, "Medium", Table5[[#This Row],[Final Amount]]>1000, "Large")} -> Small | AD3: =_xlfn.LET(_xlpm.expiry,_xlfn.XLOOKUP(Table5[[#This Row],[PromoCode]],Promo_Codes!$A$2:$A$9,Promo_Codes!$F$2:$F$9,DATE(2099,1,1)),IF(Table5[[#This Row],[OrderDate]]>_xlpm.expiry,"Expired Code Used","Valid")) -> Valid
A4: ORD-1003 | B4: 45872 | C4: Sagar Tamang | D4: 9820-297299 | E4: 45871 | F4: =IF(B4-E4<=2,"New","Returning") -> New | G4: Lalitpur | H4: Yeti Newari Bhoj | I4: Newari Khana | J4: Sukuti Sandheko | K4: 3 | L4: R-107 | M4: Khalti | O4: Delivered | P4: =IF(O4=""," NEED REVIEW","") | Q4: 4 | R4: 36 | T4: =_xlfn.CONCAT(Table5[[#This Row],[OrderID]]," | ",Table5[[#This Row],[City]]," | ",Table5[[#This Row],[ItemName]]) -> ORD-1003 | Lalitpur | Sukuti Sandheko | U4: =UPPER(Table5[[#This Row],[City]]) -> LALITPUR | V4: =LOWER(Table5[[#This Row],[PaymentMethod]]) -> khalti | W4: {=_xlfn.XLOOKUP(TRIM(Table5[[#This Row],[ItemName]]), TRIM(Menu_Price_List_tbl[ItemName]),Menu_Price_List_tbl[UnitPrice_NPR])} -> 350 | X4: =W4*K4 -> 1050 | Y4: =_xlfn.XLOOKUP(Table5[[#This Row],[City]],City_Delivery_Fee_tbl[City],City_Delivery_Fee_tbl[BaseDeliveryFee_NPR]) -> 50 | Z4: =IF(ISBLANK(Table5[[#This Row],[PromoCode]]), 0, _xlfn.LET( _xlpm.type, _xlfn.XLOOKUP(Table5[[#This Row],[PromoCode]], Promo_Codes!$A$2:$A$9, Promo_Codes!$C$2:$C$9, "Flat"), _xlpm.val, _xlfn.XLOOKUP(Table5[[#This Row],[PromoCode]], Promo_Codes!$A$2:$A$9, Promo_Codes!$D$2:$D$9, 0), IF(_xlpm.type="Percentage", Table5[[#This Row],[Order Amount]]*(_xlpm.val/100), _xlpm.val) ) ) -> 0 | AA4: =Table5[[#This Row],[Order Amount]]+Table5[[#This Row],[Delivery Fee]]-Table5[[#This Row],[Discount Amount]] -> 1100 | AB4: =_xlfn.XLOOKUP(Table5[[#This Row],[RiderID]], Rider_Directory!$F$2:$F$26, Rider_Directory!$B$2:$B$26) -> Lalitpur | AC4: {=_xlfn.IFS(Table5[[#This Row],[Final Amount]]<500, "Small", Table5[[#This Row],[Final Amount]]<=1000, "Medium", Table5[[#This Row],[Final Amount]]>1000, "Large")} -> Large | AD4: =_xlfn.LET(_xlpm.expiry,_xlfn.XLOOKUP(Table5[[#This Row],[PromoCode]],Promo_Codes!$A$2:$A$9,Promo_Codes!$F$2:$F$9,DATE(2099,1,1)),IF(Table5[[#This Row],[OrderDate]]>_xlpm.expiry,"Expired Code Used","Valid")) -> Valid
A5: ORD-1004 | B5: 45872 | C5: Suresh Magar | D5: 9822-791805 | E5: 45871 | F5: =IF(B5-E5<=2,"New","Returning") -> New | G5: Kathmandu | H5: Sekuwa Point | I5: Sekuwa | J5: Buff Sekuwa | K5: 2 | L5: R-104 | M5: eSewa | N5: MOMO20 | O5: Delivered | P5: =IF(O5=""," NEED REVIEW","") | Q5: 4 | R5: 27 | S5: Fast delivery today | T5: =_xlfn.CONCAT(Table5[[#This Row],[OrderID]]," | ",Table5[[#This Row],[City]]," | ",Table5[[#This Row],[ItemName]]) -> ORD-1004 | Kathmandu | Buff Sekuwa | U5: =UPPER(Table5[[#This Row],[City]]) -> KATHMANDU | V5: =LOWER(Table5[[#This Row],[PaymentMethod]]) -> esewa | W5: {=_xlfn.XLOOKUP(TRIM(Table5[[#This Row],[ItemName]]), TRIM(Menu_Price_List_tbl[ItemName]),Menu_Price_List_tbl[UnitPrice_NPR])} -> 380 | X5: =W5*K5 -> 760 | Y5: =_xlfn.XLOOKUP(Table5[[#This Row],[City]],City_Delivery_Fee_tbl[City],City_Delivery_Fee_tbl[BaseDeliveryFee_NPR]) -> 50 | Z5: =IF(ISBLANK(Table5[[#This Row],[PromoCode]]), 0, _xlfn.LET( _xlpm.type, _xlfn.XLOOKUP(Table5[[#This Row],[PromoCode]], Promo_Codes!$A$2:$A$9, Promo_Codes!$C$2:$C$9, "Flat"), _xlpm.val, _xlfn.XLOOKUP(Table5[[#This Row],[PromoCode]], Promo_Codes!$A$2:$A$9, Promo_Codes!$D$2:$D$9, 0), IF(_xlpm.type="Percentage", Table5[[#This Row],[Order Amount]]*(_xlpm.val/100), _xlpm.val) ) ) -> 152 | AA5: =Table5[[#This Row],[Order Amount]]+Table5[[#This Row],[Delivery Fee]]-Table5[[#This Row],[Discount Amount]] -> 658 | AB5: =_xlfn.XLOOKUP(Table5[[#This Row],[RiderID]], Rider_Directory!$F$2:$F$26, Rider_Directory!$B$2:$B$26) -> Kathmandu | AC5: {=_xlfn.IFS(Table5[[#This Row],[Final Amount]]<500, "Small", Table5[[#This Row],[Final Amount]]<=1000, "Medium", Table5[[#This Row],[Final Amount]]>1000, "Large")} -> Medium | AD5: =_xlfn.LET(_xlpm.expiry,_xlfn.XLOOKUP(Table5[[#This Row],[PromoCode]],Promo_Codes!$A$2:$A$9,Promo_Codes!$F$2:$F$9,DATE(2099,1,1)),IF(Table5[[#This Row],[OrderDate]]>_xlpm.expiry,"Expired Code Used","Valid")) -> Valid
A6: ORD-1005 | B6: 45875 | C6: Suresh Shrestha | D6: 9868-773132 | E6: 45873 | F6: =IF(B6-E6<=2,"New","Returning") -> New | G6: Kathmandu | H6: Yeti Newari Bhoj | I6: Newari Khana | J6: Bara | K6: 1 | L6: R-106 | M6: IME Pay | O6: Delivered | P6: =IF(O6=""," NEED REVIEW","") | Q6: 4 | R6: 25 | T6: =_xlfn.CONCAT(Table5[[#This Row],[OrderID]]," | ",Table5[[#This Row],[City]]," | ",Table5[[#This Row],[ItemName]]) -> ORD-1005 | Kathmandu | Bara | U6: =UPPER(Table5[[#This Row],[City]]) -> KATHMANDU | V6: =LOWER(Table5[[#This Row],[PaymentMethod]]) -> ime pay | W6: {=_xlfn.XLOOKUP(TRIM(Table5[[#This Row],[ItemName]]), TRIM(Menu_Price_List_tbl[ItemName]),Menu_Price_List_tbl[UnitPrice_NPR])} -> 160 | X6: =W6*K6 -> 160 | Y6: =_xlfn.XLOOKUP(Table5[[#This Row],[City]],City_Delivery_Fee_tbl[City],City_Delivery_Fee_tbl[BaseDeliveryFee_NPR]) -> 50 | Z6: =IF(ISBLANK(Table5[[#This Row],[PromoCode]]), 0, _xlfn.LET( _xlpm.type, _xlfn.XLOOKUP(Table5[[#This Row],[PromoCode]], Promo_Codes!$A$2:$A$9, Promo_Codes!$C$2:$C$9, "Flat"), _xlpm.val, _xlfn.XLOOKUP(Table5[[#This Row],[PromoCode]], Promo_Codes!$A$2:$A$9, Promo_Codes!$D$2:$D$9, 0), IF(_xlpm.type="Percentage", Table5[[#This Row],[Order Amount]]*(_xlpm.val/100), _xlpm.val) ) ) -> 0 | AA6: =Table5[[#This Row],[Order Amount]]+Table5[[#This Row],[Delivery Fee]]-Table5[[#This Row],[Discount Amount]] -> 210 | AB6: =_xlfn.XLOOKUP(Table5[[#This Row],[RiderID]], Rider_Directory!$F$2:$F$26, Rider_Directory!$B$2:$B$26) -> Kathmandu | AC6: {=_xlfn.IFS(Table5[[#This Row],[Final Amount]]<500, "Small", Table5[[#This Row],[Final Amount]]<=1000, "Medium", Table5[[#This Row],[Final Amount]]>1000, "Large")} -> Small | AD6: =_xlfn.LET(_xlpm.expiry,_xlfn.XLOOKUP(Table5[[#This Row],[PromoCode]],Promo_Codes!$A$2:$A$9,Promo_Codes!$F$2:$F$9,DATE(2099,1,1)),IF(Table5[[#This Row],[OrderDate]]>_xlpm.expiry,"Expired Code Used","Valid")) -> Valid
A7: ORD-1006 | B7: 45875 | C7: Sita Bhattarai | D7: 9851-313735 | E7: 45873 | F7: =IF(B7-E7<=2,"New","Returning") -> New | G7: Lalitpur | H7: Chiya Adda | I7: Beverages | J7: Milk Tea | K7: 2 | L7: R-108 | M7: Cash on Delivery | O7: Delivered | P7: =IF(O7=""," NEED REVIEW","") | Q7: 4 | R7: 22 | S7: Fast delivery today | T7: =_xlfn.CONCAT(Table5[[#This Row],[OrderID]]," | ",Table5[[#This Row],[City]]," | ",Table5[[#This Row],[ItemName]]) -> ORD-1006 | Lalitpur | Milk Tea | U7: =UPPER(Table5[[#This Row],[City]]) -> LALITPUR | V7: =LOWER(Table5[[#This Row],[PaymentMethod]]) -> cash on delivery | W7: {=_xlfn.XLOOKUP(TRIM(Table5[[#This Row],[ItemName]]), TRIM(Menu_Price_List_tbl[ItemName]),Menu_Price_List_tbl[UnitPrice_NPR])} -> 60 | X7: =W7*K7 -> 120 | Y7: =_xlfn.XLOOKUP(Table5[[#This Row],[City]],City_Delivery_Fee_tbl[City],City_Delivery_Fee_tbl[BaseDeliveryFee_NPR]) -> 50 | Z7: =IF(ISBLANK(Table5[[#This Row],[PromoCode]]), 0, _xlfn.LET( _xlpm.type, _xlfn.XLOOKUP(Table5[[#This Row],[PromoCode]], Promo_Codes!$A$2:$A$9, Promo_Codes!$C$2:$C$9, "Flat"), _xlpm.val, _xlfn.XLOOKUP(Table5[[#This Row],[PromoCode]], Promo_Codes!$A$2:$A$9, Promo_Codes!$D$2:$D$9, 0), IF(_xlpm.type="Percentage", Table5[[#This Row],[Order Amount]]*(_xlpm.val/100), _xlpm.val) ) ) -> 0 | AA7: =Table5[[#This Row],[Order Amount]]+Table5[[#This Row],[Delivery Fee]]-Table5[[#This Row],[Discount Amount]] -> 170 | AB7: =_xlfn.XLOOKUP(Table5[[#This Row],[RiderID]], Rider_Directory!$F$2:$F$26, Rider_Directory!$B$2:$B$26) -> Lalitpur | AC7: {=_xlfn.IFS(Table5[[#This Row],[Final Amount]]<500, "Small", Table5[[#This Row],[Final Amount]]<=1000, "Medium", Table5[[#This Row],[Final Amount]]>1000, "Large")} -> Small | AD7: =_xlfn.LET(_xlpm.expiry,_xlfn.XLOOKUP(Table5[[#This Row],[PromoCode]],Promo_Codes!$A$2:$A$9,Promo_Codes!$F$2:$F$9,DATE(2099,1,1)),IF(Table5[[#This Row],[OrderDate]]>_xlpm.expiry,"Expired Code Used","Valid")) -> Valid
A8: ORD-1007 | B8: 45876 | C8: Rohit Limbu | D8: 9850-201462 | E8: 45874 | F8: =IF(B8-E8<=2,"New","Returning") -> New | G8: Lalitpur | H8: Sweet Home Bakery | I8: Bakery | J8: Sel Roti (4 pcs) | K8: 1 | L8: R-109 | M8: Cash on Delivery | N8: MOMO20 | O8: Delivered | P8: =IF(O8=""," NEED REVIEW","") | Q8: 5 | R8: 34 | T8: =_xlfn.CONCAT(Table5[[#This Row],[OrderID]]," | ",Table5[[#This Row],[City]]," | ",Table5[[#This Row],[ItemName]]) -> ORD-1007 | Lalitpur | Sel Roti (4 pcs) | U8: =UPPER(Table5[[#This Row],[City]]) -> LALITPUR | V8: =LOWER(Table5[[#This Row],[PaymentMethod]]) -> cash on delivery | W8: {=_xlfn.XLOOKUP(TRIM(Table5[[#This Row],[ItemName]]), TRIM(Menu_Price_List_tbl[ItemName]),Menu_Price_List_tbl[UnitPrice_NPR])} -> 140 | X8: =W8*K8 -> 140 | Y8: =_xlfn.XLOOKUP(Table5[[#This Row],[City]],City_Delivery_Fee_tbl[City],City_Delivery_Fee_tbl[BaseDeliveryFee_NPR]) -> 50 | Z8: =IF(ISBLANK(Table5[[#This Row],[PromoCode]]), 0, _xlfn.LET( _xlpm.type, _xlfn.XLOOKUP(Table5[[#This Row],[PromoCode]], Promo_Codes!$A$2:$A$9, Promo_Codes!$C$2:$C$9, "Flat"), _xlpm.val, _xlfn.XLOOKUP(Table5[[#This Row],[PromoCode]], Promo_Codes!$A$2:$A$9, Promo_Codes!$D$2:$D$9, 0), IF(_xlpm.type="Percentage", Table5[[#This Row],[Order Amount]]*(_xlpm.val/100), _xlpm.val) ) ) -> 28 | AA8: =Table5[[#This Row],[Order Amount]]+Table5[[#This Row],[Delivery Fee]]-Table5[[#This Row],[Discount Amount]] -> 162 | AB8: =_xlfn.XLOOKUP(Table5[[#This Row],[RiderID]], Rider_Directory!$F$2:$F$26, Rider_Directory!$B$2:$B$26) -> Lalitpur | AC8: {=_xlfn.IFS(Table5[[#This Row],[Final Amount]]<500, "Small", Table5[[#This Row],[Final Amount]]<=1000, "Medium", Table5[[#This Row],[Final Amount]]>1000, "Large")} -> Small | AD8: =_xlfn.LET(_xlpm.expiry,_xlfn.XLOOKUP(Table5[[#This Row],[PromoCode]],Promo_Codes!$A$2:$A$9,Promo_Codes!$F$2:$F$9,DATE(2099,1,1)),IF(Table5[[#This Row],[OrderDate]]>_xlpm.expiry,"Expired Code Used","Valid")) -> Valid
A9: ORD-1008 | B9: 45878 | C9: Ramesh Lama | D9: 9853-705656 | E9: 45877 | F9: =IF(B9-E9<=2,"New","Returning") -> New | G9: Lalitpur | H9: Chiya Adda | I9: Beverages | J9: Lemon Soda | K9: 1 | L9: R-107 | M9: IME Pay | O9: Delivered | P9: =IF(O9=""," NEED REVIEW","") | Q9: 4 | R9: 31 | T9: =_xlfn.CONCAT(Table5[[#This Row],[OrderID]]," | ",Table5[[#This Row],[City]]," | ",Table5[[#This Row],[ItemName]]) -> ORD-1008 | Lalitpur | Lemon Soda | U9: =UPPER(Table5[[#This Row],[City]]) -> LALITPUR | V9: =LOWER(Table5[[#This Row],[PaymentMethod]]) -> ime pay | W9: {=_xlfn.XLOOKUP(TRIM(Table5[[#This Row],[ItemName]]), TRIM(Menu_Price_List_tbl[ItemName]),Menu_Price_List_tbl[UnitPrice_NPR])} -> 100 | X9: =W9*K9 -> 100 | Y9: =_xlfn.XLOOKUP(Table5[[#This Row],[City]],City_Delivery_Fee_tbl[City],City_Delivery_Fee_tbl[BaseDeliveryFee_NPR]) -> 50 | Z9: =IF(ISBLANK(Table5[[#This Row],[PromoCode]]), 0, _xlfn.LET( _xlpm.type, _xlfn.XLOOKUP(Table5[[#This Row],[PromoCode]], Promo_Codes!$A$2:$A$9, Promo_Codes!$C$2:$C$9, "Flat"), _xlpm.val, _xlfn.XLOOKUP(Table5[[#This Row],[PromoCode]], Promo_Codes!$A$2:$A$9, Promo_Codes!$D$2:$D$9, 0), IF(_xlpm.type="Percentage", Table5[[#This Row],[Order Amount]]*(_xlpm.val/100), _xlpm.val) ) ) -> 0 | AA9: =Table5[[#This Row],[Order Amount]]+Table5[[#This Row],[Delivery Fee]]-Table5[[#This Row],[Discount Amount]] -> 150 | AB9: =_xlfn.XLOOKUP(Table5[[#This Row],[RiderID]], Rider_Directory!$F$2:$F$26, Rider_Directory!$B$2:$B$26) -> Lalitpur | AC9: {=_xlfn.IFS(Table5[[#This Row],[Final Amount]]<500, "Small", Table5[[#This Row],[Final Amount]]<=1000, "Medium", Table5[[#This Row],[Final Amount]]>1000, "Large")} -> Small | AD9: =_xlfn.LET(_xlpm.expiry,_xlfn.XLOOKUP(Table5[[#This Row],[PromoCode]],Promo_Codes!$A$2:$A$9,Promo_Codes!$F$2:$F$9,DATE(2099,1,1)),IF(Table5[[#This Row],[OrderDate]]>_xlpm.expiry,"Expired Code Used","Valid")) -> Valid
A10: ORD-1009 | B10: 45879 | C10: Nisha Bista | D10: 9874-121547 | E10: 45879 | F10: =IF(B10-E10<=2,"New","Returning") -> New | G10: Biratnagar | H10: Bhattarai Momo Center | I10: Momo | J10: Buff Momo (Steamed) | K10: 2 | L10: R-118 | M10: eSewa | O10: Delivered | P10: =IF(O10=""," NEED REVIEW","") | Q10: 3 | R10: 45 | S10: quantity was less than expected | T10: =_xlfn.CONCAT(Table5[[#This Row],[OrderID]]," | ",Table5[[#This Row],[City]]," | ",Table5[[#This Row],[ItemName]]) -> ORD-1009 | Biratnagar | Buff Momo (Steamed) | U10: =UPPER(Table5[[#This Row],[City]]) -> BIRATNAGAR | V10: =LOWER(Table5[[#This Row],[PaymentMethod]]) -> esewa | W10: {=_xlfn.XLOOKUP(TRIM(Table5[[#This Row],[ItemName]]), TRIM(Menu_Price_List_tbl[ItemName]),Menu_Price_List_tbl[UnitPrice_NPR])} -> 170 | X10: =W10*K10 -> 340 | Y10: =_xlfn.XLOOKUP(Table5[[#This Row],[City]],City_Delivery_Fee_tbl[City],City_Delivery_Fee_tbl[BaseDeliveryFee_NPR]) -> 90 | Z10: =IF(ISBLANK(Table5[[#This Row],[PromoCode]]), 0, _xlfn.LET( _xlpm.type, _xlfn.XLOOKUP(Table5[[#This Row],[PromoCode]], Promo_Codes!$A$2:$A$9, Promo_Codes!$C$2:$C$9, "Flat"), _xlpm.val, _xlfn.XLOOKUP(Table5[[#This Row],[PromoCode]], Promo_Codes!$A$2:$A$9, Promo_Codes!$D$2:$D$9, 0), IF(_xlpm.type="Percentage", Table5[[#This Row],[Order Amount]]*(_xlpm.val/100), _xlpm.val) ) ) -> 0 | AA10: =Table5[[#This Row],[Order Amount]]+Table5[[#This Row],[Delivery Fee]]-Table5[[#This Row],[Discount Amount]] -> 430 | AB10: =_xlfn.XLOOKUP(Table5[[#This Row],[RiderID]], Rider_Directory!$F$2:$F$26, Rider_Directory!$B$2:$B$26) -> Biratnagar | AC10: {=_xlfn.IFS(Table5[[#This Row],[Final Amount]]<500, "Small", Table5[[#This Row],[Final Amount]]<=1000, "Medium", Table5[[#This Row],[Final Amount]]>1000, "Large")} -> Small | AD10: =_xlfn.LET(_xlpm.expiry,_xlfn.XLOOKUP(Table5[[#This Row],[PromoCode]],Promo_Codes!$A$2:$A$9,Promo_Codes!$F$2:$F$9,DATE(2099,1,1)),IF(Table5[[#This Row],[OrderDate]]>_xlpm.expiry,"Expired Code Used","Valid")) -> Valid
A11: ORD-1010 | B11: 45879 | C11: Suresh Bista | D11: 9837-504310 | E11: 45878 | F11: =IF(B11-E11<=2,"New","Returning") -> New | G11: Butwal | H11: Newa Kitchen | I11: Newari Khana | J11: Yomari | K11: 1 | L11: R-120 | M11: eSewa | N11: MOMO20 | O11: Delivered | P11: =IF(O11=""," NEED REVIEW","") | Q11: 3 | R11: 50 | S11: food was cold when it arrived | T11: =_xlfn.CONCAT(Table5[[#This Row],[OrderID]]," | ",Table5[[#This Row],[City]]," | ",Table5[[#This Row],[ItemName]]) -> ORD-1010 | Butwal | Yomari | U11: =UPPER(Table5[[#This Row],[City]]) -> BUTWAL | V11: =LOWER(Table5[[#This Row],[PaymentMethod]]) -> esewa | W11: {=_xlfn.XLOOKUP(TRIM(Table5[[#This Row],[ItemName]]), TRIM(Menu_Price_List_tbl[ItemName]),Menu_Price_List_tbl[UnitPrice_NPR])} -> 180 | X11: =W11*K11 -> 180 | Y11: =_xlfn.XLOOKUP(Table5[[#This Row],[City]],City_Delivery_Fee_tbl[City],City_Delivery_Fee_tbl[BaseDeliveryFee_NPR]) -> 85 | Z11: =IF(ISBLANK(Table5[[#This Row],[PromoCode]]), 0, _xlfn.LET( _xlpm.type, _xlfn.XLOOKUP(Table5[[#This Row],[PromoCode]], Promo_Codes!$A$2:$A$9, Promo_Codes!$C$2:$C$9, "Flat"), _xlpm.val, _xlfn.XLOOKUP(Table5[[#This Row],[PromoCode]], Promo_Codes!$A$2:$A$9, Promo_Codes!$D$2:$D$9, 0), IF(_xlpm.type="Percentage", Table5[[#This Row],[Order Amount]]*(_xlpm.val/100), _xlpm.val) ) ) -> 36 | AA11: =Table5[[#This Row],[Order Amount]]+Table5[[#This Row],[Delivery Fee]]-Table5[[#This Row],[Discount Amount]] -> 229 | AB11: =_xlfn.XLOOKUP(Table5[[#This Row],[RiderID]], Rider_Directory!$F$2:$F$26, Rider_Directory!$B$2:$B$26) -> Butwal | AC11: {=_xlfn.IFS(Table5[[#This Row],[Final Amount]]<500, "Small", Table5[[#This Row],[Final Amount]]<=1000, "Medium", Table5[[#This Row],[Final Amount]]>1000, "Large")} -> Small | AD11: =_xlfn.LET(_xlpm.expiry,_xlfn.XLOOKUP(Table5[[#This Row],[PromoCode]],Promo_Codes!$A$2:$A$9,Promo_Codes!$F$2:$F$9,DATE(2099,1,1)),IF(Table5[[#This Row],[OrderDate]]>_xlpm.expiry,"Expired Code Used","Valid")) -> Valid
A12: ORD-1011 | B12: 45880 | C12: Sabina Magar | D12: 9876-018955 | E12: 45880 | F12: =IF(B12-E12<=2,"New","Returning") -> New | G12: Dharan | H12: Newa Kitchen | I12: Newari Khana | J12: Choila (Buff) | K12: 3 | L12: R-124 | M12: eSewa | N12: MONSOON30 | O12: Delivered | P12: =IF(O12=""," NEED REVIEW","") | Q12: 4 | R12: 53 | S12: best momo in town | T12: =_xlfn.CONCAT(Table5[[#This Row],[OrderID]]," | ",Table5[[#This Row],[City]]," | ",Table5[[#This Row],[ItemName]]) -> ORD-1011 | Dharan | Choila (Buff) | U12: =UPPER(Table5[[#This Row],[City]]) -> DHARAN | V12: =LOWER(Table5[[#This Row],[PaymentMethod]]) -> esewa | W12: {=_xlfn.XLOOKUP(TRIM(Table5[[#This Row],[ItemName]]), TRIM(Menu_Price_List_tbl[ItemName]),Menu_Price_List_tbl[UnitPrice_NPR])} -> 320 | X12: =W12*K12 -> 960 | Y12: =_xlfn.XLOOKUP(Table5[[#This Row],[City]],City_Delivery_Fee_tbl[City],City_Delivery_Fee_tbl[BaseDeliveryFee_NPR]) -> 95 | Z12: =IF(ISBLANK(Table5[[#This Row],[PromoCode]]), 0, _xlfn.LET( _xlpm.type, _xlfn.XLOOKUP(Table5[[#This Row],[PromoCode]], Promo_Codes!$A$2:$A$9, Promo_Codes!$C$2:$C$9, "Flat"), _xlpm.val, _xlfn.XLOOKUP(Table5[[#This Row],[PromoCode]], Promo_Codes!$A$2:$A$9, Promo_Codes!$D$2:$D$9, 0), IF(_xlpm.type="Percentage", Table5[[#This Row],[Order Amount]]*(_xlpm.val/100), _xlpm.val) ) ) -> 30 | AA12: =Table5[[#This Row],[Order Amount]]+Table5[[#This Row],[Delivery Fee]]-Table5[[#This Row],[Discount Amount]] -> 1025 | AB12: =_xlfn.XLOOKUP(Table5[[#This Row],[RiderID]], Rider_Directory!$F$2:$F$26, Rider_Directory!$B$2:$B$26) -> Dharan | AC12: {=_xlfn.IFS(Table5[[#This Row],[Final Amount]]<500, "Small", Table5[[#This Row],[Final Amount]]<=1000, "Medium", Table5[[#This Row],[Final Amount]]>1000, "Large")} -> Large | AD12: =_xlfn.LET(_xlpm.expiry,_xlfn.XLOOKUP(Table5[[#This Row],[PromoCode]],Promo_Codes!$A$2:$A$9,Promo_Codes!$F$2:$F$9,DATE(2099,1,1)),IF(Table5[[#This Row],[OrderDate]]>_xlpm.expiry,"Expired Code Used","Valid")) -> Valid
A13: ORD-1012 | B13: 45880 | C13: Ramesh Shrestha | D13: 9800-251678 | E13: 45880 | F13: =IF(B13-E13<=2,"New","Returning") -> New | G13: Kathmandu | H13: Sweet Home Bakery | I13: Bakery | J13: Cheese Cake Slice | K13: 1 | L13: R-105 | M13: Khalti | O13: Delivered | P13: =IF(O13=""," NEED REVIEW","") | Q13: 5 | R13: 27 | S13: quality was great as always | T13: =_xlfn.CONCAT(Table5[[#This Row],[OrderID]]," | ",Table5[[#This Row],[City]]," | ",Table5[[#This Row],[ItemName]]) -> ORD-1012 | Kathmandu | Cheese Cake Slice | U13: =UPPER(Table5[[#This Row],[City]]) -> KATHMANDU | V13: =LOWER(Table5[[#This Row],[PaymentMethod]]) -> khalti | W13: {=_xlfn.XLOOKUP(TRIM(Table5[[#This Row],[ItemName]]), TRIM(Menu_Price_List_tbl[ItemName]),Menu_Price_List_tbl[UnitPrice_NPR])} -> 250 | X13: =W13*K13 -> 250 | Y13: =_xlfn.XLOOKUP(Table5[[#This Row],[City]],City_Delivery_Fee_tbl[City],City_Delivery_Fee_tbl[BaseDeliveryFee_NPR]) -> 50 | Z13: =IF(ISBLANK(Table5[[#This Row],[PromoCode]]), 0, _xlfn.LET( _xlpm.type, _xlfn.XLOOKUP(Table5[[#This Row],[PromoCode]], Promo_Codes!$A$2:$A$9, Promo_Codes!$C$2:$C$9, "Flat"), _xlpm.val, _xlfn.XLOOKUP(Table5[[#This Row],[PromoCode]], Promo_Codes!$A$2:$A$9, Promo_Codes!$D$2:$D$9, 0), IF(_xlpm.type="Percentage", Table5[[#This Row],[Order Amount]]*(_xlpm.val/100), _xlpm.val) ) ) -> 0 | AA13: =Table5[[#This Row],[Order Amount]]+Table5[[#This Row],[Delivery Fee]]-Table5[[#This Row],[Discount Amount]] -> 300 | AB13: =_xlfn.XLOOKUP(Table5[[#This Row],[RiderID]], Rider_Directory!$F$2:$F$26, Rider_Directory!$B$2:$B$26) -> Kathmandu | AC13: {=_xlfn.IFS(Table5[[#This Row],[Final Amount]]<500, "Small", Table5[[#This Row],[Final Amount]]<=1000, "Medium", Table5[[#This Row],[Final Amount]]>1000, "Large")} -> Small | AD13: =_xlfn.LET(_xlpm.expiry,_xlfn.XLOOKUP(Table5[[#This Row],[PromoCode]],Promo_Codes!$A$2:$A$9,Promo_Codes!$F$2:$F$9,DATE(2099,1,1)),IF(Table5[[#This Row],[OrderDate]]>_xlpm.expiry,"Expired Code Used","Valid")) -> Valid
A14: ORD-1013 | B14: 45881 | C14: Sunita Magar | D14: 9842-731672 | E14: 45784 | F14: =IF(B14-E14<=2,"New","Returning") -> Returning | G14: Butwal | H14: Newa Kitchen | I14: Newari Khana | J14: Aloo Achar | K14: 3 | L14: R-119 | M14: eSewa | O14: Delivered | P14: =IF(O14=""," NEED REVIEW","") | Q14: 2 | R14: 43 | T14: =_xlfn.CONCAT(Table5[[#This Row],[OrderID]]," | ",Table5[[#This Row],[City]]," | ",Table5[[#This Row],[ItemName]]) -> ORD-1013 | Butwal | Aloo Achar | U14: =UPPER(Table5[[#This Row],[City]]) -> BUTWAL | V14: =LOWER(Table5[[#This Row],[PaymentMethod]]) -> esewa | W14: {=_xlfn.XLOOKUP(TRIM(Table5[[#This Row],[ItemName]]), TRIM(Menu_Price_List_tbl[ItemName]),Menu_Price_List_tbl[UnitPrice_NPR])} -> 120 | X14: =W14*K14 -> 360 | Y14: =_xlfn.XLOOKUP(Table5[[#This Row],[City]],City_Delivery_Fee_tbl[City],City_Delivery_Fee_tbl[BaseDeliveryFee_NPR]) -> 85 | Z14: =IF(ISBLANK(Table5[[#This Row],[PromoCode]]), 0, _xlfn.LET( _xlpm.type, _xlfn.XLOOKUP(Table5[[#This Row],[PromoCode]], Promo_Codes!$A$2:$A$9, Promo_Codes!$C$2:$C$9, "Flat"), _xlpm.val, _xlfn.XLOOKUP(Table5[[#This Row],[PromoCode]], Promo_Codes!$A$2:$A$9, Promo_Codes!$D$2:$D$9, 0), IF(_xlpm.type="Percentage", Table5[[#This Row],[Order Amount]]*(_xlpm.val/100), _xlpm.val) ) ) -> 0 | AA14: =Table5[[#This Row],[Order Amount]]+Table5[[#This Row],[Delivery Fee]]-Table5[[#This Row],[Discount Amount]] -> 445 | AB14: =_xlfn.XLOOKUP(Table5[[#This Row],[RiderID]], Rider_Directory!$F$2:$F$26, Rider_Directory!$B$2:$B$26) -> Butwal | AC14: {=_xlfn.IFS(Table5[[#This Row],[Final Amount]]<500, "Small", Table5[[#This Row],[Final Amount]]<=1000, "Medium", Table5[[#This Row],[Final Amount]]>1000, "Large")} -> Small | AD14: =_xlfn.LET(_xlpm.expiry,_xlfn.XLOOKUP(Table5[[#This Row],[PromoCode]],Promo_Codes!$A$2:$A$9,Promo_Codes!$F$2:$F$9,DATE(2099,1,1)),IF(Table5[[#This Row],[OrderDate]]>_xlpm.expiry,"Expired Code Used","Valid")) -> Valid
A15: ORD-1014 | B15: 45881 | C15: Bishal Bista | D15: 9899-075116 | E15: 45880 | F15: =IF(B15-E15<=2,"New","Returning") -> New | G15: Lalitpur | H15: Newa Kitchen | I15: Newari Khana | J15: Bara | K15: 1 | L15: R-108 | M15: IME Pay | N15: FIRSTORDER | O15: Returned | P15: =IF(O15=""," NEED REVIEW","") | R15: 21 | T15: =_xlfn.CONCAT(Table5[[#This Row],[OrderID]]," | ",Table5[[#This Row],[City]]," | ",Table5[[#This Row],[ItemName]]) -> ORD-1014 | Lalitpur | Bara | U15: =UPPER(Table5[[#This Row],[City]]) -> LALITPUR | V15: =LOWER(Table5[[#This Row],[PaymentMethod]]) -> ime pay | W15: {=_xlfn.XLOOKUP(TRIM(Table5[[#This Row],[ItemName]]), TRIM(Menu_Price_List_tbl[ItemName]),Menu_Price_List_tbl[UnitPrice_NPR])} -> 160 | X15: =W15*K15 -> 160 | Y15: =_xlfn.XLOOKUP(Table5[[#This Row],[City]],City_Delivery_Fee_tbl[City],City_Delivery_Fee_tbl[BaseDeliveryFee_NPR]) -> 50 | Z15: =IF(ISBLANK(Table5[[#This Row],[PromoCode]]), 0, _xlfn.LET( _xlpm.type, _xlfn.XLOOKUP(Table5[[#This Row],[PromoCode]], Promo_Codes!$A$2:$A$9, Promo_Codes!$C$2:$C$9, "Flat"), _xlpm.val, _xlfn.XLOOKUP(Table5[[#This Row],[PromoCode]], Promo_Codes!$A$2:$A$9, Promo_Codes!$D$2:$D$9, 0), IF(_xlpm.type="Percentage", Table5[[#This Row],[Order Amount]]*(_xlpm.val/100), _xlpm.val) ) ) -> 100 | AA15: =Table5[[#This Row],[Order Amount]]+Table5[[#This Row],[Delivery Fee]]-Table5[[#This Row],[Discount Amount]] -> 110 | AB15: =_xlfn.XLOOKUP(Table5[[#This Row],[RiderID]], Rider_Directory!$F$2:$F$26, Rider_Directory!$B$2:$B$26) -> Lalitpur | AC15: {=_xlfn.IFS(Table5[[#This Row],[Final Amount]]<500, "Small", Table5[[#This Row],[Final Amount]]<=1000, "Medium", Table5[[#This Row],[Final Amount]]>1000, "Large")} -> Small | AD15: =_xlfn.LET(_xlpm.expiry,_xlfn.XLOOKUP(Table5[[#This Row],[PromoCode]],Promo_Codes!$A$2:$A$9,Promo_Codes!$F$2:$F$9,DATE(2099,1,1)),IF(Table5[[#This Row],[OrderDate]]>_xlpm.expiry,"Expired Code Used","Valid")) -> Valid
A16: ORD-1015 | B16: 45882 | C16: Manisha Bista | D16: 9886-843353 | E16: 45881 | F16: =IF(B16-E16<=2,"New","Returning") -> New | G16: Dharan | H16: Quick Snacks Corner | I16: Fast Food | J16: Veg Fried Rice | K16: 1 | L16: R-125 | M16: eSewa | N16: MONSOON30 | O16: Delivered | P16: =IF(O16=""," NEED REVIEW","") | Q16: 4 | R16: 48 | T16: =_xlfn.CONCAT(Table5[[#This Row],[OrderID]]," | ",Table5[[#This Row],[City]]," | ",Table5[[#This Row],[ItemName]]) -> ORD-1015 | Dharan | Veg Fried Rice | U16: =UPPER(Table5[[#This Row],[City]]) -> DHARAN | V16: =LOWER(Table5[[#This Row],[PaymentMethod]]) -> esewa | W16: {=_xlfn.XLOOKUP(TRIM(Table5[[#This Row],[ItemName]]), TRIM(Menu_Price_List_tbl[ItemName]),Menu_Price_List_tbl[UnitPrice_NPR])} -> 220 | X16: =W16*K16 -> 220 | Y16: =_xlfn.XLOOKUP(Table5[[#This Row],[City]],City_Delivery_Fee_tbl[City],City_Delivery_Fee_tbl[BaseDeliveryFee_NPR]) -> 95 | Z16: =IF(ISBLANK(Table5[[#This Row],[PromoCode]]), 0, _xlfn.LET( _xlpm.type, _xlfn.XLOOKUP(Table5[[#This Row],[PromoCode]], Promo_Codes!$A$2:$A$9, Promo_Codes!$C$2:$C$9, "Flat"), _xlpm.val, _xlfn.XLOOKUP(Table5[[#This Row],[PromoCode]], Promo_Codes!$A$2:$A$9, Promo_Codes!$D$2:$D$9, 0), IF(_xlpm.type="Percentage", Table5[[#This Row],[Order Amount]]*(_xlpm.val/100), _xlpm.val) ) ) -> 30 | AA16: =Table5[[#This Row],[Order Amount]]+Table5[[#This Row],[Delivery Fee]]-Table5[[#This Row],[Discount Amount]] -> 285 | AB16: =_xlfn.XLOOKUP(Table5[[#This Row],[RiderID]], Rider_Directory!$F$2:$F$26, Rider_Directory!$B$2:$B$26) -> Dharan | AC16: {=_xlfn.IFS(Table5[[#This Row],[Final Amount]]<500, "Small", Table5[[#This Row],[Final Amount]]<=1000, "Medium", Table5[[#This Row],[Final Amount]]>1000, "Large")} -> Small | AD16: =_xlfn.LET(_xlpm.expiry,_xlfn.XLOOKUP(Table5[[#This Row],[PromoCode]],Promo_Codes!$A$2:$A$9,Promo_Codes!$F$2:$F$9,DATE(2099,1,1)),IF(Table5[[#This Row],[OrderDate]]>_xlpm.expiry,"Expired Code Used","Valid")) -> Valid
A17: ORD-1016 | B17: 45882 | C17: Deepak Basnet | D17: 9844-634786 | E17: 45814 | F17: =IF(B17-E17<=2,"New","Returning") -> Returning | G17: Butwal | H17: Fast Bites | I17: Fast Food | J17: CHICKEN CHOWMEIN | K17: 2 | L17: R-120 | M17: Khalti | O17: Delivered | P17: =IF(O17=""," NEED REVIEW","") | Q17: 3 | R17: 58 | T17: =_xlfn.CONCAT(Table5[[#This Row],[OrderID]]," | ",Table5[[#This Row],[City]]," | ",Table5[[#This Row],[ItemName]]) -> ORD-1016 | Butwal | CHICKEN CHOWMEIN | U17: =UPPER(Table5[[#This Row],[City]]) -> BUTWAL | V17: =LOWER(Table5[[#This Row],[PaymentMethod]]) -> khalti | W17: {=_xlfn.XLOOKUP(TRIM(Table5[[#This Row],[ItemName]]), TRIM(Menu_Price_List_tbl[ItemName]),Menu_Price_List_tbl[UnitPrice_NPR])} -> 250 | X17: =W17*K17 -> 500 | Y17: =_xlfn.XLOOKUP(Table5[[#This Row],[City]],City_Delivery_Fee_tbl[City],City_Delivery_Fee_tbl[BaseDeliveryFee_NPR]) -> 85 | Z17: =IF(ISBLANK(Table5[[#This Row],[PromoCode]]), 0, _xlfn.LET( _xlpm.type, _xlfn.XLOOKUP(Table5[[#This Row],[PromoCode]], Promo_Codes!$A$2:$A$9, Promo_Codes!$C$2:$C$9, "Flat"), _xlpm.val, _xlfn.XLOOKUP(Table5[[#This Row],[PromoCode]], Promo_Codes!$A$2:$A$9, Promo_Codes!$D$2:$D$9, 0), IF(_xlpm.type="Percentage", Table5[[#This Row],[Order Amount]]*(_xlpm.val/100), _xlpm.val) ) ) -> 0 | AA17: =Table5[[#This Row],[Order Amount]]+Table5[[#This Row],[Delivery Fee]]-Table5[[#This Row],[Discount Amount]] -> 585 | AB17: =_xlfn.XLOOKUP(Table5[[#This Row],[RiderID]], Rider_Directory!$F$2:$F$26, Rider_Directory!$B$2:$B$26) -> Butwal | AC17: {=_xlfn.IFS(Table5[[#This Row],[Final Amount]]<500, "Small", Table5[[#This Row],[Final Amount]]<=1000, "Medium", Table5[[#This Row],[Final Amount]]>1000, "Large")} -> Medium | AD17: =_xlfn.LET(_xlpm.expiry,_xlfn.XLOOKUP(Table5[[#This Row],[PromoCode]],Promo_Codes!$A$2:$A$9,Promo_Codes!$F$2:$F$9,DATE(2099,1,1)),IF(Table5[[#This Row],[OrderDate]]>_xlpm.expiry,"Expired Code Used","Valid")) -> Valid
A18: ORD-1017 | B18: 45883 | C18: Kabita Adhikari | D18: 9838-831701 | E18: 45881 | F18: =IF(B18-E18<=2,"New","Returning") -> New | G18: Kathmandu | H18: Cafe Cup | I18: Beverages | J18: Milk Tea | K18: 2 | L18: R-105 | M18: eSewa | O18: Cancelled | P18: =IF(O18=""," NEED REVIEW","") | R18: 34 | T18: =_xlfn.CONCAT(Table5[[#This Row],[OrderID]]," | ",Table5[[#This Row],[City]]," | ",Table5[[#This Row],[ItemName]]) -> ORD-1017 | Kathmandu | Milk Tea | U18: =UPPER(Table5[[#This Row],[City]]) -> KATHMANDU | V18: =LOWER(Table5[[#This Row],[PaymentMethod]]) -> esewa | W18: {=_xlfn.XLOOKUP(TRIM(Table5[[#This Row],[ItemName]]), TRIM(Menu_Price_List_tbl[ItemName]),Menu_Price_List_tbl[UnitPrice_NPR])} -> 60 | X18: =W18*K18 -> 120 | Y18: =_xlfn.XLOOKUP(Table5[[#This Row],[City]],City_Delivery_Fee_tbl[City],City_Delivery_Fee_tbl[BaseDeliveryFee_NPR]) -> 50 | Z18: =IF(ISBLANK(Table5[[#This Row],[PromoCode]]), 0, _xlfn.LET( _xlpm.type, _xlfn.XLOOKUP(Table5[[#This Row],[PromoCode]], Promo_Codes!$A$2:$A$9, Promo_Codes!$C$2:$C$9, "Flat"), _xlpm.val, _xlfn.XLOOKUP(Table5[[#This Row],[PromoCode]], Promo_Codes!$A$2:$A$9, Promo_Codes!$D$2:$D$9, 0), IF(_xlpm.type="Percentage", Table5[[#This Row],[Order Amount]]*(_xlpm.val/100), _xlpm.val) ) ) -> 0 | AA18: =Table5[[#This Row],[Order Amount]]+Table5[[#This Row],[Delivery Fee]]-Table5[[#This Row],[Discount Amount]] -> 170 | AB18: =_xlfn.XLOOKUP(Table5[[#This Row],[RiderID]], Rider_Directory!$F$2:$F$26, Rider_Directory!$B$2:$B$26) -> Kathmandu | AC18: {=_xlfn.IFS(Table5[[#This Row],[Final Amount]]<500, "Small", Table5[[#This Row],[Final Amount]]<=1000, "Medium", Table5[[#This Row],[Final Amount]]>1000, "Large")} -> Small | AD18: =_xlfn.LET(_xlpm.expiry,_xlfn.XLOOKUP(Table5[[#This Row],[PromoCode]],Promo_Codes!$A$2:$A$9,Promo_Codes!$F$2:$F$9,DATE(2099,1,1)),IF(Table5[[#This Row],[OrderDate]]>_xlpm.expiry,"Expired Code Used","Valid")) -> Valid
A19: ORD-1018 | B19: 45884 | C19: Nisha Thapa | D19: 9858-649208 | E19: 45787 | F19: =IF(B19-E19<=2,"New","Returning") -> Returning | G19: Kathmandu | H19: Bhatti Sekuwa Corner | I19: Sekuwa | J19: Buff Sekuwa | K19: 1 | L19: R-106 | M19: Khalti | O19: Delivered | P19: =IF(O19=""," NEED REVIEW","") | Q19: 5 | R19: 26 | T19: =_xlfn.CONCAT(Table5[[#This Row],[OrderID]]," | ",Table5[[#This Row],[City]]," | ",Table5[[#This Row],[ItemName]]) -> ORD-1018 | Kathmandu | Buff Sekuwa | U19: =UPPER(Table5[[#This Row],[City]]) -> KATHMANDU | V19: =LOWER(Table5[[#This Row],[PaymentMethod]]) -> khalti | W19: {=_xlfn.XLOOKUP(TRIM(Table5[[#This Row],[ItemName]]), TRIM(Menu_Price_List_tbl[ItemName]),Menu_Price_List_tbl[UnitPrice_NPR])} -> 380 | X19: =W19*K19 -> 380 | Y19: =_xlfn.XLOOKUP(Table5[[#This Row],[City]],City_Delivery_Fee_tbl[City],City_Delivery_Fee_tbl[BaseDeliveryFee_NPR]) -> 50 | Z19: =IF(ISBLANK(Table5[[#This Row],[PromoCode]]), 0, _xlfn.LET( _xlpm.type, _xlfn.XLOOKUP(Table5[[#This Row],[PromoCode]], Promo_Codes!$A$2:$A$9, Promo_Codes!$C$2:$C$9, "Flat"), _xlpm.val, _xlfn.XLOOKUP(Table5[[#This Row],[PromoCode]], Promo_Codes!$A$2:$A$9, Promo_Codes!$D$2:$D$9, 0), IF(_xlpm.type="Percentage", Table5[[#This Row],[Order Amount]]*(_xlpm.val/100), _xlpm.val) ) ) -> 0 | AA19: =Table5[[#This Row],[Order Amount]]+Table5[[#This Row],[Delivery Fee]]-Table5[[#This Row],[Discount Amount]] -> 430 | AB19: =_xlfn.XLOOKUP(Table5[[#This Row],[RiderID]], Rider_Directory!$F$2:$F$26, Rider_Directory!$B$2:$B$26) -> Kathmandu | AC19: {=_xlfn.IFS(Table5[[#This Row],[Final Amount]]<500, "Small", Table5[[#This Row],[Final Amount]]<=1000, "Medium", Table5[[#This Row],[Final Amount]]>1000, "Large")} -> Small | AD19: =_xlfn.LET(_xlpm.expiry,_xlfn.XLOOKUP(Table5[[#This Row],[PromoCode]],Promo_Codes!$A$2:$A$9,Promo_Codes!$F$2:$F$9,DATE(2099,1,1)),IF(Table5[[#This Row],[OrderDate]]>_xlpm.expiry,"Expired Code Used","Valid")) -> Valid
A20: ORD-1019 | B20: 45885 | C20: Ramesh Tamang | D20: 9868-656355 | E20: 45885 | F20: =IF(B20-E20<=2,"New","Returning") -> New | G20: Kathmandu | H20: Yeti Newari Bhoj | I20: Newari Khana | J20: Sukuti Sandheko | K20: 3 | L20: R-101 | M20: eSewa | O20: Delivered | P20: =IF(O20=""," NEED REVIEW","") | Q20: 4 | R20: 32 | T20: =_xlfn.CONCAT(Table5[[#This Row],[OrderID]]," | ",Table5[[#This Row],[City]]," | ",Table5[[#This Row],[ItemName]]) -> ORD-1019 | Kathmandu | Sukuti Sandheko | U20: =UPPER(Table5[[#This Row],[City]]) -> KATHMANDU | V20: =LOWER(Table5[[#This Row],[PaymentMethod]]) -> esewa | W20: {=_xlfn.XLOOKUP(TRIM(Table5[[#This Row],[ItemName]]), TRIM(Menu_Price_List_tbl[ItemName]),Menu_Price_List_tbl[UnitPrice_NPR])} -> 350 | X20: =W20*K20 -> 1050 | Y20: =_xlfn.XLOOKUP(Table5[[#This Row],[City]],City_Delivery_Fee_tbl[City],City_Delivery_Fee_tbl[BaseDeliveryFee_NPR]) -> 50 | Z20: =IF(ISBLANK(Table5[[#This Row],[PromoCode]]), 0, _xlfn.LET( _xlpm.type, _xlfn.XLOOKUP(Table5[[#This Row],[PromoCode]], Promo_Codes!$A$2:$A$9, Promo_Codes!$C$2:$C$9, "Flat"), _xlpm.val, _xlfn.XLOOKUP(Table5[[#This Row],[PromoCode]], Promo_Codes!$A$2:$A$9, Promo_Codes!$D$2:$D$9, 0), IF(_xlpm.type="Percentage", Table5[[#This Row],[Order Amount]]*(_xlpm.val/100), _xlpm.val) ) ) -> 0 | AA20: =Table5[[#This Row],[Order Amount]]+Table5[[#This Row],[Delivery Fee]]-Table5[[#This Row],[Discount Amount]] -> 1100 | AB20: =_xlfn.XLOOKUP(Table5[[#This Row],[RiderID]], Rider_Directory!$F$2:$F$26, Rider_Directory!$B$2:$B$26) -> Kathmandu | AC20: {=_xlfn.IFS(Table5[[#This Row],[Final Amount]]<500, "Small", Table5[[#This Row],[Final Amount]]<=1000, "Medium", Table5[[#This Row],[Final Amount]]>1000, "Large")} -> Large | AD20: =_xlfn.LET(_xlpm.expiry,_xlfn.XLOOKUP(Table5[[#This Row],[PromoCode]],Promo_Codes!$A$2:$A$9,Promo_Codes!$F$2:$F$9,DATE(2099,1,1)),IF(Table5[[#This Row],[OrderDate]]>_xlpm.expiry,"Expired Code Used","Valid")) -> Valid
A21: ORD-1020 | B21: 45886 | C21: Kiran Maharjan | D21: 9817-180023 | E21: 45886 | F21: =IF(B21-E21<=2,"New","Returning") -> New | G21: Chitwan | H21: Fast Bites | I21: Fast Food | J21: Chicken Burger | K21: 3 | L21: R-123 | M21: eSewa | O21: Returned | P21: =IF(O21=""," NEED REVIEW","") | R21: 56 | S21: fine I guess | T21: =_xlfn.CONCAT(Table5[[#This Row],[OrderID]]," | ",Table5[[#This Row],[City]]," | ",Table5[[#This Row],[ItemName]]) -> ORD-1020 | Chitwan | Chicken Burger | U21: =UPPER(Table5[[#This Row],[City]]) -> CHITWAN | V21: =LOWER(Table5[[#This Row],[PaymentMethod]]) -> esewa | W21: {=_xlfn.XLOOKUP(TRIM(Table5[[#This Row],[ItemName]]), TRIM(Menu_Price_List_tbl[ItemName]),Menu_Price_List_tbl[UnitPrice_NPR])} -> 280 | X21: =W21*K21 -> 840 | Y21: =_xlfn.XLOOKUP(Table5[[#This Row],[City]],City_Delivery_Fee_tbl[City],City_Delivery_Fee_tbl[BaseDeliveryFee_NPR]) -> 80 | Z21: =IF(ISBLANK(Table5[[#This Row],[PromoCode]]), 0, _xlfn.LET( _xlpm.type, _xlfn.XLOOKUP(Table5[[#This Row],[PromoCode]], Promo_Codes!$A$2:$A$9, Promo_Codes!$C$2:$C$9, "Flat"), _xlpm.val, _xlfn.XLOOKUP(Table5[[#This Row],[PromoCode]], Promo_Codes!$A$2:$A$9, Promo_Codes!$D$2:$D$9, 0), IF(_xlpm.type="Percentage", Table5[[#This Row],[Order Amount]]*(_xlpm.val/100), _xlpm.val) ) ) -> 0 | AA21: =Table5[[#This Row],[Order Amount]]+Table5[[#This Row],[Delivery Fee]]-Table5[[#This Row],[Discount Amount]] -> 920 | AB21: =_xlfn.XLOOKUP(Table5[[#This Row],[RiderID]], Rider_Directory!$F$2:$F$26, Rider_Directory!$B$2:$B$26) -> Chitwan | AC21: {=_xlfn.IFS(Table5[[#This Row],[Final Amount]]<500, "Small", Table5[[#This Row],[Final Amount]]<=1000, "Medium", Table5[[#This Row],[Final Amount]]>1000, "Large")} -> Medium | AD21: =_xlfn.LET(_xlpm.expiry,_xlfn.XLOOKUP(Table5[[#This Row],[PromoCode]],Promo_Codes!$A$2:$A$9,Promo_Codes!$F$2:$F$9,DATE(2099,1,1)),IF(Table5[[#This Row],[OrderDate]]>_xlpm.expiry,"Expired Code Used","Valid")) -> Valid
A22: ORD-1021 | B22: 45886 | C22: Rohit Limbu | D22: 9850-201462 | E22: 45874 | F22: =IF(B22-E22<=2,"New","Returning") -> Returning | G22: Bhaktapur | H22: Chiya Adda | I22: Beverages | J22: Black Coffee | K22: 1 | L22: R-111 | M22: Khalti | O22: Delivered | P22: =IF(O22=""," NEED REVIEW","") | Q22: 4 | R22: 24 | T22: =_xlfn.CONCAT(Table5[[#This Row],[OrderID]]," | ",Table5[[#This Row],[City]]," | ",Table5[[#This Row],[ItemName]]) -> ORD-1021 | Bhaktapur | Black Coffee | U22: =UPPER(Table5[[#This Row],[City]]) -> BHAKTAPUR | V22: =LOWER(Table5[[#This Row],[PaymentMethod]]) -> khalti | W22: {=_xlfn.XLOOKUP(TRIM(Table5[[#This Row],[ItemName]]), TRIM(Menu_Price_List_tbl[ItemName]),Menu_Price_List_tbl[UnitPrice_NPR])} -> 90 | X22: =W22*K22 -> 90 | Y22: =_xlfn.XLOOKUP(Table5[[#This Row],[City]],City_Delivery_Fee_tbl[City],City_Delivery_Fee_tbl[BaseDeliveryFee_NPR]) -> 55 | Z22: =IF(ISBLANK(Table5[[#This Row],[PromoCode]]), 0, _xlfn.LET( _xlpm.type, _xlfn.XLOOKUP(Table5[[#This Row],[PromoCode]], Promo_Codes!$A$2:$A$9, Promo_Codes!$C$2:$C$9, "Flat"), _xlpm.val, _xlfn.XLOOKUP(Table5[[#This Row],[PromoCode]], Promo_Codes!$A$2:$A$9, Promo_Codes!$D$2:$D$9, 0), IF(_xlpm.type="Percentage", Table5[[#This Row],[Order Amount]]*(_xlpm.val/100), _xlpm.val) ) ) -> 0 | AA22: =Table5[[#This Row],[Order Amount]]+Table5[[#This Row],[Delivery Fee]]-Table5[[#This Row],[Discount Amount]] -> 145 | AB22: =_xlfn.XLOOKUP(Table5[[#This Row],[RiderID]], Rider_Directory!$F$2:$F$26, Rider_Directory!$B$2:$B$26) -> Bhaktapur | AC22: {=_xlfn.IFS(Table5[[#This Row],[Final Amount]]<500, "Small", Table5[[#This Row],[Final Amount]]<=1000, "Medium", Table5[[#This Row],[Final Amount]]>1000, "Large")} -> Small | AD22: =_xlfn.LET(_xlpm.expiry,_xlfn.XLOOKUP(Table5[[#This Row],[PromoCode]],Promo_Codes!$A$2:$A$9,Promo_Codes!$F$2:$F$9,DATE(2099,1,1)),IF(Table5[[#This Row],[OrderDate]]>_xlpm.expiry,"Expired Code Used","Valid")) -> Valid
A23: ORD-1022 | B23: 45887 | C23: Kiran Bhattarai | D23: 9851-732904 | E23: 45886 | F23: =IF(B23-E23<=2,"New","Returning") -> New | G23: Kathmandu | H23: Thakali Ghar | I23: Thakali Set | J23: Mutton Thakali Set | K23: 3 | L23: R-105 | M23: eSewa | O23: Returned | P23: =IF(O23=""," NEED REVIEW","") | R23: 23 | S23: fine I guess | T23: =_xlfn.CONCAT(Table5[[#This Row],[OrderID]]," | ",Table5[[#This Row],[City]]," | ",Table5[[#This Row],[ItemName]]) -> ORD-1022 | Kathmandu | Mutton Thakali Set | U23: =UPPER(Table5[[#This Row],[City]]) -> KATHMANDU | V23: =LOWER(Table5[[#This Row],[PaymentMethod]]) -> esewa | W23: {=_xlfn.XLOOKUP(TRIM(Table5[[#This Row],[ItemName]]), TRIM(Menu_Price_List_tbl[ItemName]),Menu_Price_List_tbl[UnitPrice_NPR])} -> 650 | X23: =W23*K23 -> 1950 | Y23: =_xlfn.XLOOKUP(Table5[[#This Row],[City]],City_Delivery_Fee_tbl[City],City_Delivery_Fee_tbl[BaseDeliveryFee_NPR]) -> 50 | Z23: =IF(ISBLANK(Table5[[#This Row],[PromoCode]]), 0, _xlfn.LET( _xlpm.type, _xlfn.XLOOKUP(Table5[[#This Row],[PromoCode]], Promo_Codes!$A$2:$A$9, Promo_Codes!$C$2:$C$9, "Flat"), _xlpm.val, _xlfn.XLOOKUP(Table5[[#This Row],[PromoCode]], Promo_Codes!$A$2:$A$9, Promo_Codes!$D$2:$D$9, 0), IF(_xlpm.type="Percentage", Table5[[#This Row],[Order Amount]]*(_xlpm.val/100), _xlpm.val) ) ) -> 0 | AA23: =Table5[[#This Row],[Order Amount]]+Table5[[#This Row],[Delivery Fee]]-Table5[[#This Row],[Discount Amount]] -> 2000 | AB23: =_xlfn.XLOOKUP(Table5[[#This Row],[RiderID]], Rider_Directory!$F$2:$F$26, Rider_Directory!$B$2:$B$26) -> Kathmandu | AC23: {=_xlfn.IFS(Table5[[#This Row],[Final Amount]]<500, "Small", Table5[[#This Row],[Final Amount]]<=1000, "Medium", Table5[[#This Row],[Final Amount]]>1000, "Large")} -> Large | AD23: =_xlfn.LET(_xlpm.expiry,_xlfn.XLOOKUP(Table5[[#This Row],[PromoCode]],Promo_Codes!$A$2:$A$9,Promo_Codes!$F$2:$F$9,DATE(2099,1,1)),IF(Table5[[#This Row],[OrderDate]]>_xlpm.expiry,"Expired Code Used","Valid")) -> Valid
A24: ORD-1023 | B24: 45888 | C24: Ramesh Bista | D24: 9860-926030 | E24: 45888 | F24: =IF(B24-E24<=2,"New","Returning") -> New | G24: Lalitpur | H24: Quick Snacks Corner | I24: Fast Food | J24: veg fried rice | K24: 3 | L24: R-108 | M24: Khalti | O24: Delivered | P24: =IF(O24=""," NEED REVIEW","") | Q24: 5 | R24: 37 | T24: =_xlfn.CONCAT(Table5[[#This Row],[OrderID]]," | ",Table5[[#This Row],[City]]," | ",Table5[[#This Row],[ItemName]]) -> ORD-1023 | Lalitpur | veg fried rice | U24: =UPPER(Table5[[#This Row],[City]]) -> LALITPUR | V24: =LOWER(Table5[[#This Row],[PaymentMethod]]) -> khalti | W24: {=_xlfn.XLOOKUP(TRIM(Table5[[#This Row],[ItemName]]), TRIM(Menu_Price_List_tbl[ItemName]),Menu_Price_List_tbl[UnitPrice_NPR])} -> 220 | X24: =W24*K24 -> 660 | Y24: =_xlfn.XLOOKUP(Table5[[#This Row],[City]],City_Delivery_Fee_tbl[City],City_Delivery_Fee_tbl[BaseDeliveryFee_NPR]) -> 50 | Z24: =IF(ISBLANK(Table5[[#This Row],[PromoCode]]), 0, _xlfn.LET( _xlpm.type, _xlfn.XLOOKUP(Table5[[#This Row],[PromoCode]], Promo_Codes!$A$2:$A$9, Promo_Codes!$C$2:$C$9, "Flat"), _xlpm.val, _xlfn.XLOOKUP(Table5[[#This Row],[PromoCode]], Promo_Codes!$A$2:$A$9, Promo_Codes!$D$2:$D$9, 0), IF(_xlpm.type="Percentage", Table5[[#This Row],[Order Amount]]*(_xlpm.val/100), _xlpm.val) ) ) -> 0 | AA24: =Table5[[#This Row],[Order Amount]]+Table5[[#This Row],[Delivery Fee]]-Table5[[#This Row],[Discount Amount]] -> 710 | AB24: =_xlfn.XLOOKUP(Table5[[#This Row],[RiderID]], Rider_Directory!$F$2:$F$26, Rider_Directory!$B$2:$B$26) -> Lalitpur | AC24: {=_xlfn.IFS(Table5[[#This Row],[Final Amount]]<500, "Small", Table5[[#This Row],[Final Amount]]<=1000, "Medium", Table5[[#This Row],[Final Amount]]>1000, "Large")} -> Medium | AD24: =_xlfn.LET(_xlpm.expiry,_xlfn.XLOOKUP(Table5[[#This Row],[PromoCode]],Promo_Codes!$A$2:$A$9,Promo_Codes!$F$2:$F$9,DATE(2099,1,1)),IF(Table5[[#This Row],[OrderDate]]>_xlpm.expiry,"Expired Code Used","Valid")) -> Valid
A25: ORD-1024 | B25: 45889 | C25: Gopal Karki | D25: 9869-919220 | E25: 45888 | F25: =IF(B25-E25<=2,"New","Returning") -> New | G25: Kathmandu | H25: Quick Snacks Corner | I25: Fast Food | J25: chicken burger | K25: 2 | L25: R-105 | M25: IME Pay | O25: Returned | P25: =IF(O25=""," NEED REVIEW","") | R25: 31 | T25: =_xlfn.CONCAT(Table5[[#This Row],[OrderID]]," | ",Table5[[#This Row],[City]]," | ",Table5[[#This Row],[ItemName]]) -> ORD-1024 | Kathmandu | chicken burger | U25: =UPPER(Table5[[#This Row],[City]]) -> KATHMANDU | V25: =LOWER(Table5[[#This Row],[PaymentMethod]]) -> ime pay | W25: {=_xlfn.XLOOKUP(TRIM(Table5[[#This Row],[ItemName]]), TRIM(Menu_Price_List_tbl[ItemName]),Menu_Price_List_tbl[UnitPrice_NPR])} -> 280 | X25: =W25*K25 -> 560 | Y25: =_xlfn.XLOOKUP(Table5[[#This Row],[City]],City_Delivery_Fee_tbl[City],City_Delivery_Fee_tbl[BaseDeliveryFee_NPR]) -> 50 | Z25: =IF(ISBLANK(Table5[[#This Row],[PromoCode]]), 0, _xlfn.LET( _xlpm.type, _xlfn.XLOOKUP(Table5[[#This Row],[PromoCode]], Promo_Codes!$A$2:$A$9, Promo_Codes!$C$2:$C$9, "Flat"), _xlpm.val, _xlfn.XLOOKUP(Table5[[#This Row],[PromoCode]], Promo_Codes!$A$2:$A$9, Promo_Codes!$D$2:$D$9, 0), IF(_xlpm.type="Percentage", Table5[[#This Row],[Order Amount]]*(_xlpm.val/100), _xlpm.val) ) ) -> 0 | AA25: =Table5[[#This Row],[Order Amount]]+Table5[[#This Row],[Delivery Fee]]-Table5[[#This Row],[Discount Amount]] -> 610 | AB25: =_xlfn.XLOOKUP(Table5[[#This Row],[RiderID]], Rider_Directory!$F$2:$F$26, Rider_Directory!$B$2:$B$26) -> Kathmandu | AC25: {=_xlfn.IFS(Table5[[#This Row],[Final Amount]]<500, "Small", Table5[[#This Row],[Final Amount]]<=1000, "Medium", Table5[[#This Row],[Final Amount]]>1000, "Large")} -> Medium | AD25: =_xlfn.LET(_xlpm.expiry,_xlfn.XLOOKUP(Table5[[#This Row],[PromoCode]],Promo_Codes!$A$2:$A$9,Promo_Codes!$F$2:$F$9,DATE(2099,1,1)),IF(Table5[[#This Row],[OrderDate]]>_xlpm.expiry,"Expired Code Used","Valid")) -> Valid
A26: ORD-1025 | B26: 45890 | C26: Rina Adhikari | D26: 9867-272042 | E26: 45743 | F26: =IF(B26-E26<=2,"New","Returning") -> Returning | G26: Biratnagar | H26: Cafe Cup | I26: Beverages | J26: MANGO JUICE | K26: 1 | L26: R-117 | M26: Khalti | O26: Delivered | P26: =IF(O26=""," NEED REVIEW","") | Q26: 5 | R26: 34 | S26: quality was great as always | T26: =_xlfn.CONCAT(Table5[[#This Row],[OrderID]]," | ",Table5[[#This Row],[City]]," | ",Table5[[#This Row],[ItemName]]) -> ORD-1025 | Biratnagar | MANGO JUICE | U26: =UPPER(Table5[[#This Row],[City]]) -> BIRATNAGAR | V26: =LOWER(Table5[[#This Row],[PaymentMethod]]) -> khalti | W26: {=_xlfn.XLOOKUP(TRIM(Table5[[#This Row],[ItemName]]), TRIM(Menu_Price_List_tbl[ItemName]),Menu_Price_List_tbl[UnitPrice_NPR])} -> 120 | X26: =W26*K26 -> 120 | Y26: =_xlfn.XLOOKUP(Table5[[#This Row],[City]],City_Delivery_Fee_tbl[City],City_Delivery_Fee_tbl[BaseDeliveryFee_NPR]) -> 90 | Z26: =IF(ISBLANK(Table5[[#This Row],[PromoCode]]), 0, _xlfn.LET( _xlpm.type, _xlfn.XLOOKUP(Table5[[#This Row],[PromoCode]], Promo_Codes!$A$2:$A$9, Promo_Codes!$C$2:$C$9, "Flat"), _xlpm.val, _xlfn.XLOOKUP(Table5[[#This Row],[PromoCode]], Promo_Codes!$A$2:$A$9, Promo_Codes!$D$2:$D$9, 0), IF(_xlpm.type="Percentage", Table5[[#This Row],[Order Amount]]*(_xlpm.val/100), _xlpm.val) ) ) -> 0 | AA26: =Table5[[#This Row],[Order Amount]]+Table5[[#This Row],[Delivery Fee]]-Table5[[#This Row],[Discount Amount]] -> 210 | AB26: =_xlfn.XLOOKUP(Table5[[#This Row],[RiderID]], Rider_Directory!$F$2:$F$26, Rider_Directory!$B$2:$B$26) -> Biratnagar | AC26: {=_xlfn.IFS(Table5[[#This Row],[Final Amount]]<500, "Small", Table5[[#This Row],[Final Amount]]<=1000, "Medium", Table5[[#This Row],[Final Amount]]>1000, "Large")} -> Small | AD26: =_xlfn.LET(_xlpm.expiry,_xlfn.XLOOKUP(Table5[[#This Row],[PromoCode]],Promo_Codes!$A$2:$A$9,Promo_Codes!$F$2:$F$9,DATE(2099,1,1)),IF(Table5[[#This Row],[OrderDate]]>_xlpm.expiry,"Expired Code Used","Valid")) -> Valid
A27: ORD-1026 | B27: 45890 | C27: Pradeep Maharjan | D27: 9848-372616 | E27: 45889 | F27: =IF(B27-E27<=2,"New","Returning") -> New | G27: Pokhara | H27: Fast Bites | I27: Fast Food | J27: Chicken Chowmein | K27: 1 | L27: R-112 | M27: IME Pay | O27: Delivered | P27: =IF(O27=""," NEED REVIEW","") | Q27: 5 | R27: 23 | S27: packaging was nice | T27: =_xlfn.CONCAT(Table5[[#This Row],[OrderID]]," | ",Table5[[#This Row],[City]]," | ",Table5[[#This Row],[ItemName]]) -> ORD-1026 | Pokhara | Chicken Chowmein | U27: =UPPER(Table5[[#This Row],[City]]) -> POKHARA | V27: =LOWER(Table5[[#This Row],[PaymentMethod]]) -> ime pay | W27: {=_xlfn.XLOOKUP(TRIM(Table5[[#This Row],[ItemName]]), TRIM(Menu_Price_List_tbl[ItemName]),Menu_Price_List_tbl[UnitPrice_NPR])} -> 250 | X27: =W27*K27 -> 250 | Y27: =_xlfn.XLOOKUP(Table5[[#This Row],[City]],City_Delivery_Fee_tbl[City],City_Delivery_Fee_tbl[BaseDeliveryFee_NPR]) -> 70 | Z27: =IF(ISBLANK(Table5[[#This Row],[PromoCode]]), 0, _xlfn.LET( _xlpm.type, _xlfn.XLOOKUP(Table5[[#This Row],[PromoCode]], Promo_Codes!$A$2:$A$9, Promo_Codes!$C$2:$C$9, "Flat"), _xlpm.val, _xlfn.XLOOKUP(Table5[[#This Row],[PromoCode]], Promo_Codes!$A$2:$A$9, Promo_Codes!$D$2:$D$9, 0), IF(_xlpm.type="Percentage", Table5[[#This Row],[Order Amount]]*(_xlpm.val/100), _xlpm.val) ) ) -> 0 | AA27: =Table5[[#This Row],[Order Amount]]+Table5[[#This Row],[Delivery Fee]]-Table5[[#This Row],[Discount Amount]] -> 320 | AB27: =_xlfn.XLOOKUP(Table5[[#This Row],[RiderID]], Rider_Directory!$F$2:$F$26, Rider_Directory!$B$2:$B$26) -> Pokhara | AC27: {=_xlfn.IFS(Table5[[#This Row],[Final Amount]]<500, "Small", Table5[[#This Row],[Final Amount]]<=1000, "Medium", Table5[[#This Row],[Final Amount]]>1000, "Large")} -> Small | AD27: =_xlfn.LET(_xlpm.expiry,_xlfn.XLOOKUP(Table5[[#This Row],[PromoCode]],Promo_Codes!$A$2:$A$9,Promo_Codes!$F$2:$F$9,DATE(2099,1,1)),IF(Table5[[#This Row],[OrderDate]]>_xlpm.expiry,"Expired Code Used","Valid")) -> Valid
A28: ORD-1027 | B28: 45891 | C28: Sagar Poudel | D28: 9896-937293 | E28: 45891 | F28: =IF(B28-E28<=2,"New","Returning") -> New | G28: Kathmandu | H28: Quick Snacks Corner | I28: Fast Food | J28: Chicken Chowmein | K28: 3 | L28: R-102 | M28: Khalti | N28: MONSOON30 | O28: Delivered | P28: =IF(O28=""," NEED REVIEW","") | R28: 32 | T28: =_xlfn.CONCAT(Table5[[#This Row],[OrderID]]," | ",Table5[[#This Row],[City]]," | ",Table5[[#This Row],[ItemName]]) -> ORD-1027 | Kathmandu | Chicken Chowmein | U28: =UPPER(Table5[[#This Row],[City]]) -> KATHMANDU | V28: =LOWER(Table5[[#This Row],[PaymentMethod]]) -> khalti | W28: {=_xlfn.XLOOKUP(TRIM(Table5[[#This Row],[ItemName]]), TRIM(Menu_Price_List_tbl[ItemName]),Menu_Price_List_tbl[UnitPrice_NPR])} -> 250 | X28: =W28*K28 -> 750 | Y28: =_xlfn.XLOOKUP(Table5[[#This Row],[City]],City_Delivery_Fee_tbl[City],City_Delivery_Fee_tbl[BaseDeliveryFee_NPR]) -> 50 | Z28: =IF(ISBLANK(Table5[[#This Row],[PromoCode]]), 0, _xlfn.LET( _xlpm.type, _xlfn.XLOOKUP(Table5[[#This Row],[PromoCode]], Promo_Codes!$A$2:$A$9, Promo_Codes!$C$2:$C$9, "Flat"), _xlpm.val, _xlfn.XLOOKUP(Table5[[#This Row],[PromoCode]], Promo_Codes!$A$2:$A$9, Promo_Codes!$D$2:$D$9, 0), IF(_xlpm.type="Percentage", Table5[[#This Row],[Order Amount]]*(_xlpm.val/100), _xlpm.val) ) ) -> 30 | AA28: =Table5[[#This Row],[Order Amount]]+Table5[[#This Row],[Delivery Fee]]-Table5[[#This Row],[Discount Amount]] -> 770 | AB28: =_xlfn.XLOOKUP(Table5[[#This Row],[RiderID]], Rider_Directory!$F$2:$F$26, Rider_Directory!$B$2:$B$26) -> Kathmandu | AC28: {=_xlfn.IFS(Table5[[#This Row],[Final Amount]]<500, "Small", Table5[[#This Row],[Final Amount]]<=1000, "Medium", Table5[[#This Row],[Final Amount]]>1000, "Large")} -> Medium | AD28: =_xlfn.LET(_xlpm.expiry,_xlfn.XLOOKUP(Table5[[#This Row],[PromoCode]],Promo_Codes!$A$2:$A$9,Promo_Codes!$F$2:$F$9,DATE(2099,1,1)),IF(Table5[[#This Row],[OrderDate]]>_xlpm.expiry,"Expired Code Used","Valid")) -> Valid
